<mujoco model="go2_robot">
  <compiler angle="radian" meshdir="meshes/"/>

  <default>
    <joint damping="0.1" armature="0.01" frictionloss="0.05"/>
  </default>

  <asset>
    <!-- Go2 STL mesh files (convert from DAE) -->
    <mesh name="base" file="base.STL"/>
    <mesh name="hip" file="hip.STL"/>
    <mesh name="thigh" file="thigh.STL"/>
    <mesh name="thigh_mirror" file="thigh_mirror.STL"/>
    <mesh name="calf" file="calf.STL"/>
    <mesh name="calf_mirror" file="calf_mirror.STL"/>
    <mesh name="foot" file="foot.STL"/>
  </asset>

  <worldbody>
    <!-- Go2 Robot -->
    <body name="base" pos="0 0 0.34">
      <!-- Base link inertial from URDF -->
      <inertial pos="0.021112 0 -0.005366" quat="1 0 0 0" mass="6.921" 
                diaginertia="0.02448 0.098077 0.107"/>
      <joint name="floating_base_joint" type="free" limited="false" actuatorfrclimited="false"/>
      <geom type="mesh" contype="0" conaffinity="0" group="1" density="0" rgba="1 1 1 1" mesh="base"/>
      <geom type="mesh" rgba="1 1 1 1" mesh="base"/>
      
      <!-- Front Left Leg -->
      <body name="FL_hip" pos="0.1934 0.0465 0">
        <inertial pos="-0.0054 0.00194 -0.000105" quat="1 0 0 0" mass="0.678" 
                  diaginertia="0.00048 0.000884 0.000596"/>
        <joint name="FL_hip_joint" pos="0 0 0" axis="1 0 0" range="-1.0472 1.0472" actuatorfrcrange="-23.7 23.7"/>
        <geom type="mesh" contype="0" conaffinity="0" group="1" density="0" rgba="1 1 1 1" mesh="hip"/>
        <geom type="mesh" rgba="1 1 1 1" mesh="hip"/>
        
        <body name="FL_thigh" pos="0 0.0955 0">
          <inertial pos="-0.00374 -0.0223 -0.0327" quat="1 0 0 0" mass="1.152" 
                    diaginertia="0.00584 0.0058 0.00103"/>
          <joint name="FL_thigh_joint" pos="0 0 0" axis="0 1 0" range="-1.5708 3.4907" actuatorfrcrange="-23.7 23.7"/>
          <geom type="mesh" contype="0" conaffinity="0" group="1" density="0" rgba="1 1 1 1" mesh="thigh"/>
          <geom type="mesh" rgba="1 1 1 1" mesh="thigh"/>
          
          <body name="FL_calf" pos="0 0 -0.213">
            <inertial pos="0.00548 -0.000975 -0.115" quat="1 0 0 0" mass="0.154" 
                      diaginertia="0.00108 0.0011 3.29E-05"/>
            <joint name="FL_calf_joint" pos="0 0 0" axis="0 1 0" range="-2.7227 -0.83776" actuatorfrcrange="-35.55 35.55"/>
            <geom type="mesh" contype="0" conaffinity="0" group="1" density="0" rgba="1 1 1 1" mesh="calf"/>
            <geom type="mesh" rgba="1 1 1 1" mesh="calf"/>
            
            <!-- Foot -->
            <body name="FL_foot" pos="0 0 -0.213">
              <inertial pos="0 0 0" quat="1 0 0 0" mass="0.04" diaginertia="9.6e-06 9.6e-06 9.6e-06"/>
              <geom type="mesh" contype="0" conaffinity="0" group="1" density="0" rgba="1 1 1 1" mesh="foot"/>
              <geom name="FL_foot" pos="-0.002 0 0" type="sphere" size="0.022" rgba="0.2 0.2 0.2 1"/>
            </body>
          </body>
        </body>
      </body>
      
      <!-- Front Right Leg -->
      <body name="FR_hip" pos="0.1934 -0.0465 0">
        <inertial pos="-0.0054 -0.00194 -0.000105" quat="1 0 0 0" mass="0.678" 
                  diaginertia="0.00048 0.000884 0.000596"/>
        <joint name="FR_hip_joint" pos="0 0 0" axis="1 0 0" range="-1.0472 1.0472" actuatorfrcrange="-23.7 23.7"/>
        <geom type="mesh" contype="0" conaffinity="0" group="1" density="0" rgba="1 1 1 1" mesh="hip" euler="3.1415 0 0"/>
        <geom type="mesh" rgba="1 1 1 1" mesh="hip" euler="3.1415 0 0"/>
        
        <body name="FR_thigh" pos="0 -0.0955 0">
          <inertial pos="-0.00374 0.0223 -0.0327" quat="1 0 0 0" mass="1.152" 
                    diaginertia="0.00584 0.0058 0.00103"/>
          <joint name="FR_thigh_joint" pos="0 0 0" axis="0 1 0" range="-1.5708 3.4907" actuatorfrcrange="-23.7 23.7"/>
          <geom type="mesh" contype="0" conaffinity="0" group="1" density="0" rgba="1 1 1 1" mesh="thigh_mirror"/>
          <geom type="mesh" rgba="1 1 1 1" mesh="thigh_mirror"/>
          
          <body name="FR_calf" pos="0 0 -0.213">
            <inertial pos="0.00548 0.000975 -0.115" quat="1 0 0 0" mass="0.154" 
                      diaginertia="0.00108 0.0011 3.29E-05"/>
            <joint name="FR_calf_joint" pos="0 0 0" axis="0 1 0" range="-2.7227 -0.83776" actuatorfrcrange="-35.55 35.55"/>
            <geom type="mesh" contype="0" conaffinity="0" group="1" density="0" rgba="1 1 1 1" mesh="calf_mirror"/>
            <geom type="mesh" rgba="1 1 1 1" mesh="calf_mirror"/>
            
            <body name="FR_foot" pos="0 0 -0.213">
              <inertial pos="0 0 0" quat="1 0 0 0" mass="0.04" diaginertia="9.6e-06 9.6e-06 9.6e-06"/>
              <geom type="mesh" contype="0" conaffinity="0" group="1" density="0" rgba="1 1 1 1" mesh="foot"/>
              <geom name="FR_foot" pos="-0.002 0 0" type="sphere" size="0.022" rgba="0.2 0.2 0.2 1"/>
            </body>
          </body>
        </body>
      </body>
      
      <!-- Rear Left Leg -->
      <body name="RL_hip" pos="-0.1934 0.0465 0">
        <inertial pos="0.0054 0.00194 -0.000105" quat="1 0 0 0" mass="0.678" 
                  diaginertia="0.00048 0.000884 0.000596"/>
        <joint name="RL_hip_joint" pos="0 0 0" axis="1 0 0" range="-1.0472 1.0472" actuatorfrcrange="-23.7 23.7"/>
        <geom type="mesh" contype="0" conaffinity="0" group="1" density="0" rgba="1 1 1 1" mesh="hip" euler="0 3.1415 0"/>
        <geom type="mesh" rgba="1 1 1 1" mesh="hip" euler="0 3.1415 0"/>
        
        <body name="RL_thigh" pos="0 0.0955 0">
          <inertial pos="-0.00374 -0.0223 -0.0327" quat="1 0 0 0" mass="1.152" 
                    diaginertia="0.00584 0.0058 0.00103"/>
          <joint name="RL_thigh_joint" pos="0 0 0" axis="0 1 0" range="-0.5236 4.5379" actuatorfrcrange="-23.7 23.7"/>
          <geom type="mesh" contype="0" conaffinity="0" group="1" density="0" rgba="1 1 1 1" mesh="thigh"/>
          <geom type="mesh" rgba="1 1 1 1" mesh="thigh"/>
          
          <body name="RL_calf" pos="0 0 -0.213">
            <inertial pos="0.00548 -0.000975 -0.115" quat="1 0 0 0" mass="0.154" 
                      diaginertia="0.00108 0.0011 3.29E-05"/>
            <joint name="RL_calf_joint" pos="0 0 0" axis="0 1 0" range="-2.7227 -0.83776" actuatorfrcrange="-35.55 35.55"/>
            <geom type="mesh" contype="0" conaffinity="0" group="1" density="0" rgba="1 1 1 1" mesh="calf"/>
            <geom type="mesh" rgba="1 1 1 1" mesh="calf"/>
            
            <body name="RL_foot" pos="0 0 -0.213">
              <inertial pos="0 0 0" quat="1 0 0 0" mass="0.04" diaginertia="9.6e-06 9.6e-06 9.6e-06"/>
              <geom type="mesh" contype="0" conaffinity="0" group="1" density="0" rgba="1 1 1 1" mesh="foot"/>
              <geom name="RL_foot" pos="-0.002 0 0" type="sphere" size="0.022" rgba="0.2 0.2 0.2 1"/>
            </body>
          </body>
        </body>
      </body>
      
      <!-- Rear Right Leg -->
      <body name="RR_hip" pos="-0.1934 -0.0465 0">
        <inertial pos="0.0054 -0.00194 -0.000105" quat="1 0 0 0" mass="0.678" 
                  diaginertia="0.00048 0.000884 0.000596"/>
        <joint name="RR_hip_joint" pos="0 0 0" axis="1 0 0" range="-1.0472 1.0472" actuatorfrcrange="-23.7 23.7"/>
        <geom type="mesh" contype="0" conaffinity="0" group="1" density="0" rgba="1 1 1 1" mesh="hip" euler="3.1415 3.1415 0"/>
        <geom type="mesh" rgba="1 1 1 1" mesh="hip" euler="3.1415 3.1415 0"/>
        
        <body name="RR_thigh" pos="0 -0.0955 0">
          <inertial pos="-0.00374 0.0223 -0.0327" quat="1 0 0 0" mass="1.152" 
                    diaginertia="0.00584 0.0058 0.00103"/>
          <joint name="RR_thigh_joint" pos="0 0 0" axis="0 1 0" range="-0.5236 4.5379" actuatorfrcrange="-23.7 23.7"/>
          <geom type="mesh" contype="0" conaffinity="0" group="1" density="0" rgba="1 1 1 1" mesh="thigh_mirror"/>
          <geom type="mesh" rgba="1 1 1 1" mesh="thigh_mirror"/>
          
          <body name="RR_calf" pos="0 0 -0.213">
            <inertial pos="0.00548 0.000975 -0.115" quat="1 0 0 0" mass="0.154" 
                      diaginertia="0.00108 0.0011 3.29E-05"/>
            <joint name="RR_calf_joint" pos="0 0 0" axis="0 1 0" range="-2.7227 -0.83776" actuatorfrcrange="-35.55 35.55"/>
            <geom type="mesh" contype="0" conaffinity="0" group="1" density="0" rgba="1 1 1 1" mesh="calf_mirror"/>
            <geom type="mesh" rgba="1 1 1 1" mesh="calf_mirror"/>
            
            <body name="RR_foot" pos="0 0 -0.213">
              <inertial pos="0 0 0" quat="1 0 0 0" mass="0.04" diaginertia="9.6e-06 9.6e-06 9.6e-06"/>
              <geom type="mesh" contype="0" conaffinity="0" group="1" density="0" rgba="1 1 1 1" mesh="foot"/>
              <geom name="RR_foot" pos="-0.002 0 0" type="sphere" size="0.022" rgba="0.2 0.2 0.2 1"/>
            </body>
          </body>
        </body>
      </body>
    </body>
  </worldbody>
  
  <actuator>
    <motor name="FL_hip_joint" joint="FL_hip_joint"/>
    <motor name="FL_thigh_joint" joint="FL_thigh_joint"/>
    <motor name="FL_calf_joint" joint="FL_calf_joint"/>
    <motor name="FR_hip_joint" joint="FR_hip_joint"/>
    <motor name="FR_thigh_joint" joint="FR_thigh_joint"/>
    <motor name="FR_calf_joint" joint="FR_calf_joint"/>
    <motor name="RL_hip_joint" joint="RL_hip_joint"/>
    <motor name="RL_thigh_joint" joint="RL_thigh_joint"/>
    <motor name="RL_calf_joint" joint="RL_calf_joint"/>
    <motor name="RR_hip_joint" joint="RR_hip_joint"/>
    <motor name="RR_thigh_joint" joint="RR_thigh_joint"/>
    <motor name="RR_calf_joint" joint="RR_calf_joint"/>
  </actuator>
</mujoco>